Workbook
Name Slicer_Category: #N/A
Name Slicer_Region: #N/A
Name Slicer_Segment: #N/A
Name Slicer_Year: #N/A

Sheet Executive

Sheet Operational

Sheet Customers 
M13: Name | P13: Total Spend | R13: Days Since Last Order
M14: ='Pivot Tables'!B95 -> Lauren Leatherbury | P14: ='Pivot Tables'!C95 -> 2741.204 | R14: =DATE(2018,12,31) - 'Pivot Tables'!D95 -> 250
M15: ='Pivot Tables'!B96 -> John Lucas | P15: ='Pivot Tables'!C96 -> 2725.256 | R15: =DATE(2018,12,31) - 'Pivot Tables'!D96 -> 615
M16: ='Pivot Tables'!B97 -> Bill Overfelt | P16: ='Pivot Tables'!C97 -> 2682.728 | R16: =DATE(2018,12,31) - 'Pivot Tables'!D97 -> 138
M17: ='Pivot Tables'!B98 -> Nicole Hansen | P17: ='Pivot Tables'!C98 -> 2673.29 | R17: =DATE(2018,12,31) - 'Pivot Tables'!D98 -> 190
M18: ='Pivot Tables'!B99 -> Beth Thompson | P18: ='Pivot Tables'!C99 -> 2567.656 | R18: =DATE(2018,12,31) - 'Pivot Tables'!D99 -> 337
M19: ='Pivot Tables'!B100 -> Eleni Mccrary | P19: ='Pivot Tables'!C100 -> 2567.01 | R19: =DATE(2018,12,31) - 'Pivot Tables'!D100 -> 133
M20: ='Pivot Tables'!B101 -> Mary Zewe | P20: ='Pivot Tables'!C101 -> 2564.906 | R20: =DATE(2018,12,31) - 'Pivot Tables'!D101 -> 283
M21: ='Pivot Tables'!B102 -> Deanra Eno | P21: ='Pivot Tables'!C102 -> 2550.874 | R21: =DATE(2018,12,31) - 'Pivot Tables'!D102 -> 719
M22: ='Pivot Tables'!B103 -> Amy Hunt | P22: ='Pivot Tables'!C103 -> 2495.3916 | R22: =DATE(2018,12,31) - 'Pivot Tables'!D103 -> 231
M23: ='Pivot Tables'!B104 -> Charles Crestani | P23: ='Pivot Tables'!C104 -> 2471.65 | R23: =DATE(2018,12,31) - 'Pivot Tables'!D104 -> 107

Sheet Pivot Tables
B3: Total Revenue | D3: Total Profit | F3: #Orders | H3: Avg. Order Value | J3: Row Labels | K3: #Customer
B4: 2297200.9 | D4: 286397.02 | F4: 5009 | H4: 458.61467 | J4: Recent Customers | K4: 104
B6: Avg. Selling Price | D6: YoY Growth | F6: Avg. Spend per Customer | H6: Total Quantity | J6: Row Labels | K6: #Customer
B7: 60.655371 | D7: 0.43266271 | F7: 2896.8485 | H7: 37873 | J7: Loyal Customers | K7: 247
B9: Profit Margin | D9: Avg. Days to Ship | F9: #Products | H9: #Customer | J9: Row Labels | K9: #Customer
B10: 0.12467217 | D10: 3.9584751 | F10: 1862 | H10: 793 | J10: At Risk | K10: 179
P14: Segment | Q14: Champions
B15: Row Labels | C15: Total Revenue | D15: Total Revenue2 | F15: Segments | G15: Total Revenue
B16: January | C16: 109456.69 | D16: 109456.69 | F16: Consumer | G16: 1161401.3 | I16: Row Labels | J16: Growth Rate | K16: Growth Rate2 | P16: Row Labels | Q16: Total Revenue
B17: February | C17: 68546.472 | D17: 68546.472 | F17: Corporate | G17: 706146.37 | I17: 2015 | J17: 0 | K17: 0 | L17: =I17 -> 2015 | M17: =J17 -> 0 | N17: =M17 -> 0 | P17: Phones | Q17: 105948.85
B18: March | C18: 191665.31 | D18: 191665.31 | F18: Home Office | G18: 429653.15 | I18: 2016 | J18: 0.019259423 | K18: 0.019259423 | L18: =I18 -> 2016 | M18: =J18 -> 0.019259423 | N18: =M18 -> 0.019259423 | P18: Chairs | Q18: 90549.216
B19: April | C19: 136953.7 | D19: 136953.7 | F19: Grand Total | G19: 2297200.9 | I19: 2017 | J19: 0.27507626 | K19: 0.27507626 | L19: =I19 -> 2017 | M19: =J19 -> 0.27507626 | N19: =M19 -> 0.27507626 | P19: Binders | Q19: 68852.646
B20: May | C20: 146361.95 | D20: 146361.95 | I20: 2018 | J20: 0.19558143 | K20: 0.19558143 | L20: =I20 -> 2018 | M20: =J20 -> 0.19558143 | N20: =M20 -> 0.19558143 | P20: Storage | Q20: 62000.508
B21: June | C21: 161335.71 | D21: 161335.71 | I21: Grand Total | J21: 0.46817349 | K21: 0.46817349 | P21: Tables | Q21: 52648.575
B22: July | C22: 148170.64 | D22: 148170.64 | P22: Grand Total | Q22: 379999.79
B23: August | C23: 154153.16 | D23: 154153.16 | F23: Region | G23: Total Revenue
B24: September | C24: 304631.16 | D24: 304631.16 | F24: West | G24: 764634.45
B25: October | C25: 204727.05 | D25: 204727.05 | F25: East | G25: 611734.3
B26: November | C26: 330681.74 | D26: 330681.74 | F26: Central | G26: 518800.13
B27: December | C27: 340517.29 | D27: 340517.29 | F27: South | G27: 402031.98 | K27: Row Labels | L27: #Customer
B28: Grand Total | C28: 2297200.9 | D28: 2297200.9 | F28: Grand Total | G28: 2297200.9 | K28: Loyal Customers | L28: 247
K29: At Risk | L29: 179
K30: Champions | L30: 116
K31: Recent Customers | L31: 104
K32: Big Spenders | L32: 85
K33: Needs Attention | L33: 62
B34: Row Labels | C34: #Orders | D34: Avg Days to Ship | K34: Grand Total | L34: 793
B35: Same Day | C35: 264 | D35: 0.044198895
B36: First Class | C36: 787 | D36: 2.1820546
B37: Second Class | C37: 964 | D37: 3.2380463
B38: Standard Class | C38: 2994 | D38: 5.0072051
B39: Grand Total | C39: 5009 | D39: 3.9584751 | G39: Row Labels | H39: Total Revenue | I39: Total Profit
G40: Furniture | H40: 741999.8 | I40: 18451.273
G41: Office Supplies | H41: 719047.03 | I41: 122490.8
G42: Technology | H42: 836154.03 | I42: 145454.95
G43: Grand Total | H43: 2297200.9 | I43: 286397.02
B45: Row Labels | C45: Total Profit | D45: State | E45: Total Profit
B46: California | C46: 59398.313 | D46: {=B46:C87} -> California | E46: 59398.313
B47: New York | C47: 58177.834 | D47: New York | E47: 58177.834
B48: Washington | C48: 24405.797 | D48: Washington | E48: 24405.797
...
